Workbook

Sheet README
A1: ESCA HSE | AI, IoT, Integrations & Audit Sample Data
A2: Synthetic AI/IoT events, integrations, notifications, audit and automation datasets
A4: Convention | B4: Details
A5: Dataset type | B5: 100% synthetic training/development data; no real employee or medical data.
A6: Reference snapshot | B6: 2026-08-13, timezone Africa/Cairo.
A7: Source references | B7: ESCA_HSE_Management_System.html (17-module mockup) and ESCA_HSE_Project_Plan.pdf.
A8: Identifiers | B8: Cross-file IDs are intentionally consistent. Do not rename primary keys without updating foreign keys.
A9: Dates | B9: Stored as real Excel dates/timestamps. Formula flags use the fixed as-of values in each Summary sheet.
A10: Status fields | B10: Use approved values from the Master workbook Status_Values sheet; do not invent new states silently.
A11: Health data | B11: Clinic and exam rows contain synthetic high-level fitness/restriction data only; no diagnoses or medications.
A12: Usage | B12: Suitable for schema design, import testing, API development, UI wiring, automation tests and demo rehearsal.
A14: Sheet | B14: Owner | C14: Purpose | D14: Rows
A15: IoT_Sensors | B15: Member 5 | C15: Synthetic sensor registry | D15: 8
A16: Sensor_Readings | B16: Member 5 | C16: Synthetic time-series readings | D16: 32
A17: Cameras | B17: Member 5 | C17: Synthetic computer-vision devices | D17: 8
A18: AI_Models | B18: Member 5 | C18: Synthetic AI model registry and validation metrics | D18: 8
A19: AI_Events | B19: Member 5 | C19: Synthetic AI detections | D19: 18
A20: Wearable_Devices | B20: Member 5 | C20: Synthetic wearable assignments | D20: 10
A21: Wearable_Events | B21: Member 5 | C21: Synthetic wearable alerts | D21: 10
A22: Integrations | B22: Member 2 | C22: External integration catalogue | D22: 6
A23: API_Logs | B23: Member 2 | C23: Synthetic integration request logs | D23: 20
A24: Integration_Outbox | B24: Member 2 | C24: Retry-safe integration outbox sample | D24: 6
A25: QA_Sessions | B25: Member 5 | C25: Admin conversational Q&A sessions | D25: 4
A26: QA_Messages | B26: Member 5 | C26: Synthetic admin Q&A messages and policy blocks | D26: 10
... A33: Automation_Actions | B33: Member 4 | C33: Spring API action requests, retries and audit links | D33: 12

Sheet Summary
A1: ESCA HSE | AI, IoT, Integration & Audit Summary
A2: Synthetic digital events, service integrations and automation evidence
A3: As-of date | B3: 46247
A4: As-of timestamp | B4: 46247.375
A6: KPI | B6: Value | D6: Sensor alert | E6: Count
A7: Sensor readings | B7: =COUNTA(Sensor_Readings!$A$5:$A$100) -> 32 | D7: NORMAL | E7: =COUNTIF(Sensor_Readings!$K$5:$K$100,"NORMAL") -> 19
A8: Critical sensor readings | B8: =COUNTIF(Sensor_Readings!$K$5:$K$100,"CRITICAL") -> 8 | D8: WARNING | E8: =COUNTIF(Sensor_Readings!$K$5:$K$100,"WARNING") -> 5
A9: Open AI events | B9: =COUNTIF(AI_Events!$I$5:$I$100,"OPEN") -> 5 | D9: CRITICAL | E9: =COUNTIF(Sensor_Readings!$K$5:$K$100,"CRITICAL") -> 8
A10: Integrations not connected | B10: =COUNTA(Integrations!$A$5:$A$100)-COUNTIF(Integrations!$I$5:$I$100,"CONNECTED") -> 1
A11: Unread notifications | B11: =COUNTIF(Notifications!$K$5:$K$100,"UNREAD") -> 10
A12: Automation failed actions | B12: =SUM(Automation_Runs!$I$5:$I$100) -> 1

Sheet IoT_Sensors
A1: ESCA HSE | IoT_Sensors | B1: ESCA HSE | IoT_Sensors | C1: ESCA HSE | IoT_Sensors | D1: ESCA HSE | IoT_Sensors | E1: ESCA HSE | IoT_Sensors | F1: ESCA HSE | IoT_Sensors | G1: ESCA HSE | IoT_Sensors | H1: ESCA HSE | IoT_Sensors | I1: ESCA HSE | IoT_Sensors | J1: ESCA HSE | IoT_Sensors | K1: ESCA HSE | IoT_Sensors | L1: ESCA HSE | IoT_Sensors
A2: Synthetic sensor registry | Owner: Member 5 | Synthetic sample data | Snapshot: 2026-08-13 | B2: Synthetic sensor registry | Owner: Member 5 | Synthetic sample data | Snapshot: 2026-08-13 | C2: Synthetic sensor registry | Owner: Member 5 | Synthetic sample data | Snapshot: 2026-08-13 | D2: Synthetic sensor registry | Owner: Member 5 | Synthetic sample data | Snapshot: 2026-08-13 | E2: Synthetic sensor registry | Owner: Member 5 | Synthetic sample data | Snapshot: 2026-08-13 | F2: Synthetic sensor registry | Owner: Member 5 | Synthetic sample data | Snapshot: 2026-08-13 | G2: Synthetic sensor registry | Owner: Member 5 | Synthetic sample data | Snapshot: 2026-08-13 | H2: Synthetic sensor registry | Owner: Member 5 | Synthetic sample data | Snapshot: 2026-08-13 | I2: Synthetic sensor registry | Owner: Member 5 | Synthetic sample data | Snapshot: 2026-08-13 | J2: Synthetic sensor registry | Owner: Member 5 | Synthetic sample data | Snapshot: 2026-08-13 | K2: Synthetic sensor registry | Owner: Member 5 | Synthetic sample data | Snapshot: 2026-08-13 | L2: Synthetic sensor registry | Owner: Member 5 | Synthetic sample data | Snapshot: 2026-08-13
A4: sensor_id | B4: sensor_type | C4: department_id | D4: zone_id | E4: unit | F4: safe_min | G4: safe_max | H4: warning_min | I4: warning_max | J4: status | K4: last_calibrated_at | L4: next_calibration_at
A5: SNS-VOC-01 | B5: VOC | C5: DEP-MAINT | D5: ZN-M01 | E5: ppm | F5: 0 | G5: 50 | H5: 0 | I5: 100 | J5: ACTIVE | K5: 46204 | L5: 46388
A6: SNS-NS-11 | B6: NOISE | C6: DEP-PROD-A | D6: ZN-A1 | E6: dB | F6: 0 | G6: 85 | H6: 0 | I6: 90 | J6: ACTIVE | K6: 46208 | L6: 46392
A7: SNS-HT-05 | B7: WBGT | C7: DEP-PROD-A | D7: ZN-A2 | E7: C | F7: 0 | G7: 28 | H7: 0 | I7: 30 | J7: ACTIVE | K7: 46206 | L7: 46390
A8: SNS-AC-01 | B8: ACETYLENE_LEL | C8: DEP-MAINT | D8: ZN-M01 | E8: %LEL | F8: 0 | G8: 10 | H8: 0 | I8: 20 | J8: ACTIVE | K8: 46207 | L8: 46391
A9: SNS-CS-02 | B9: OXYGEN | C9: DEP-UTIL | D9: ZN-U02 | E9: % | F9: 20 | G9: 23 | H9: 19.5 | I9: 23.5 | J9: ACTIVE | K9: 46235 | L9: 46327
A10: SNS-PM-03 | B10: PM2_5 | C10: DEP-WH | D10: ZN-W01 | E10: ug/m3 | F10: 0 | G10: 25 | H10: 0 | I10: 35 | J10: ACTIVE | K10: 46188 | L10: 46371
A11: SNS-TMP-01 | B11: TEMPERATURE | C11: DEP-QC | D11: ZN-Q01 | E11: C | F11: 18 | G11: 27 | H11: 15 | I11: 30 | J11: ACTIVE | K11: 46213 | L11: 46397
A12: SNS-GAS-09 | B12: LPG_LEL | C12: DEP-WH | D12: ZN-CHEM | E12: %LEL | F12: 0 | G12: 0.5 | H12: 0 | I12: 1 | J12: MAINTENANCE | K12: 46143 | L12: 46249

Sheet Sensor_Readings
A1: ESCA HSE | Sensor_Readings | B1: ESCA HSE | Sensor_Readings | C1: ESCA HSE | Sensor_Readings | D1: ESCA HSE | Sensor_Readings | E1: ESCA HSE | Sensor_Readings | F1: ESCA HSE | Sensor_Readings | G1: ESCA HSE | Sensor_Readings | H1: ESCA HSE | Sensor_Readings | I1: ESCA HSE | Sensor_Readings | J1: ESCA HSE | Sensor_Readings | K1: ESCA HSE | Sensor_Readings
A2: Synthetic time-series readings | Owner: Member 5 | Synthetic sample data | Snapshot: 2026-08-13 | B2: Synthetic time-series readings | Owner: Member 5 | Synthetic sample data | Snapshot: 2026-08-13 | C2: Synthetic time-series readings | Owner: Member 5 | Synthetic sample data | Snapshot: 2026-08-13 | D2: Synthetic time-series readings | Owner: Member 5 | Synthetic sample data | Snapshot: 2026-08-13 | E2: Synthetic time-series readings | Owner: Member 5 | Synthetic sample data | Snapshot: 2026-08-13 | F2: Synthetic time-series readings | Owner: Member 5 | Synthetic sample data | Snapshot: 2026-08-13 | G2: Synthetic time-series readings | Owner: Member 5 | Synthetic sample data | Snapshot: 2026-08-13 | H2: Synthetic time-series readings | Owner: Member 5 | Synthetic sample data | Snapshot: 2026-08-13 | I2: Synthetic time-series readings | Owner: Member 5 | Synthetic sample data | Snapshot: 2026-08-13 | J2: Synthetic time-series readings | Owner: Member 5 | Synthetic sample data | Snapshot: 2026-08-13 | K2: Synthetic time-series readings | Owner: Member 5 | Synthetic sample data | Snapshot: 2026-08-13
A4: reading_id | B4: sensor_id | C4: captured_at | D4: value | E4: unit | F4: quality | G4: safe_min | H4: safe_max | I4: warning_min | J4: warning_max | K4: alert_level
A5: RDG-0001 | B5: SNS-VOC-01 | C5: 46247.218 | D5: 42 | E5: ppm | F5: GOOD | G5: 0 | H5: 50 | I5: 0 | J5: 100 | K5: =IF(OR(D5<I5,D5>J5),"CRITICAL",IF(OR(D5<G5,D5>H5),"WARNING","NORMAL")) -> NORMAL
A6: RDG-0002 | B6: SNS-VOC-01 | C6: 46247.265 | D6: 56 | E6: ppm | F6: GOOD | G6: 0 | H6: 50 | I6: 0 | J6: 100 | K6: =IF(OR(D6<I6,D6>J6),"CRITICAL",IF(OR(D6<G6,D6>H6),"WARNING","NORMAL")) -> WARNING
A7: RDG-0003 | B7: SNS-VOC-01 | C7: 46247.311 | D7: 48 | E7: ppm | F7: GOOD | G7: 0 | H7: 50 | I7: 0 | J7: 100 | K7: =IF(OR(D7<I7,D7>J7),"CRITICAL",IF(OR(D7<G7,D7>H7),"WARNING","NORMAL")) -> NORMAL
A8: RDG-0004 | B8: SNS-VOC-01 | C8: 46247.358 | D8: 39 | E8: ppm | F8: GOOD | G8: 0 | H8: 50 | I8: 0 | J8: 100 | K8: =IF(OR(D8<I8,D8>J8),"CRITICAL",IF(OR(D8<G8,D8>H8),"WARNING","NORMAL")) -> NORMAL
A9: RDG-0005 | B9: SNS-NS-11 | C9: 46247.238 | D9: 82 | E9: dB | F9: GOOD | G9: 0 | H9: 85 | I9: 0 | J9: 90 | K9: =IF(OR(D9<I9,D9>J9),"CRITICAL",IF(OR(D9<G9,D9>H9),"WARNING","NORMAL")) -> NORMAL
A10: RDG-0006 | B10: SNS-NS-11 | C10: 46247.284 | D10: 88 | E10: dB | F10: GOOD | G10: 0 | H10: 85 | I10: 0 | J10: 90 | K10: =IF(OR(D10<I10,D10>J10),"CRITICAL",IF(OR(D10<G10,D10>H10),"WARNING","NORMAL")) -> WARNING
A11: RDG-0007 | B11: SNS-NS-11 | C11: 46247.331 | D11: 91 | E11: dB | F11: GOOD | G11: 0 | H11: 85 | I11: 0 | J11: 90 | K11: =IF(OR(D11<I11,D11>J11),"CRITICAL",IF(OR(D11<G11,D11>H11),"WARNING","NORMAL")) -> CRITICAL
A12: RDG-0008 | B12: SNS-NS-11 | C12: 46247.335 | D12: 84 | E12: dB | F12: GOOD | G12: 0 | H12: 85 | I12: 0 | J12: 90 | K12: =IF(OR(D12<I12,D12>J12),"CRITICAL",IF(OR(D12<G12,D12>H12),"WARNING","NORMAL")) -> NORMAL
A13: RDG-0009 | B13: SNS-HT-05 | C13: 46247.215 | D13: 27.2 | E13: C | F13: GOOD | G13: 0 | H13: 28 | I13: 0 | J13: 30 | K13: =IF(OR(D13<I13,D13>J13),"CRITICAL",IF(OR(D13<G13,D13>H13),"WARNING","NORMAL")) -> NORMAL
A14: RDG-0010 | B14: SNS-HT-05 | C14: 46247.262 | D14: 29.4 | E14: C | F14: GOOD | G14: 0 | H14: 28 | I14: 0 | J14: 30 | K14: =IF(OR(D14<I14,D14>J14),"CRITICAL",IF(OR(D14<G14,D14>H14),"WARNING","NORMAL")) -> WARNING
A15: RDG-0011 | B15: SNS-HT-05 | C15: 46247.308 | D15: 30.5 | E15: C | F15: GOOD | G15: 0 | H15: 28 | I15: 0 | J15: 30 | K15: =IF(OR(D15<I15,D15>J15),"CRITICAL",IF(OR(D15<G15,D15>H15),"WARNING","NORMAL")) -> CRITICAL
A16: RDG-0012 | B16: SNS-HT-05 | C16: 46247.355 | D16: 28.1 | E16: C | F16: GOOD | G16: 0 | H16: 28 | I16: 0 | J16: 30 | K16: =IF(OR(D16<I16,D16>J16),"CRITICAL",IF(OR(D16<G16,D16>H16),"WARNING","NORMAL")) -> WARNING
... A36: RDG-0032 | B36: SNS-GAS-09 | C36: 46247.369 | D36: 0.2 | E36: %LEL | F36: SUSPECT | G36: 0 | H36: 0.5 | I36: 0 | J36: 1 | K36: =IF(OR(D36<I36,D36>J36),"CRITICAL",IF(OR(D36<G36,D36>H36),"WARNING","NORMAL")) -> NORMAL

Sheet Cameras
A1: ESCA HSE | Cameras | B1: ESCA HSE | Cameras | C1: ESCA HSE | Cameras | D1: ESCA HSE | Cameras | E1: ESCA HSE | Cameras | F1: ESCA HSE | Cameras | G1: ESCA HSE | Cameras | H1: ESCA HSE | Cameras
A2: Synthetic computer-vision devices | Owner: Member 5 | Synthetic sample data | Snapshot: 2026-08-13 | B2: Synthetic computer-vision devices | Owner: Member 5 | Synthetic sample data | Snapshot: 2026-08-13 | C2: Synthetic computer-vision devices | Owner: Member 5 | Synthetic sample data | Snapshot: 2026-08-13 | D2: Synthetic computer-vision devices | Owner: Member 5 | Synthetic sample data | Snapshot: 2026-08-13 | E2: Synthetic computer-vision devices | Owner: Member 5 | Synthetic sample data | Snapshot: 2026-08-13 | F2: Synthetic computer-vision devices | Owner: Member 5 | Synthetic sample data | Snapshot: 2026-08-13 | G2: Synthetic computer-vision devices | Owner: Member 5 | Synthetic sample data | Snapshot: 2026-08-13 | H2: Synthetic computer-vision devices | Owner: Member 5 | Synthetic sample data | Snapshot: 2026-08-13
A4: camera_id | B4: zone_id | C4: capabilities | D4: model_version | E4: processing_fps | F4: status | G4: last_heartbeat_at | H4: stream_ref
A5: CAM-A-01 | B5: ZN-A1 | C5: PPE;RESTRICTED_ZONE | D5: ppe-v3.4 | E5: 24 | F5: ACTIVE | G5: 46247.374 | H5: rtsp://demo.local/cam-a-01
A6: CAM-A-07 | B6: ZN-A1 | C6: PPE;FIRE;MAN_DOWN | D6: ppe-v3.4 | E6: 24 | F6: ACTIVE | G6: 46247.374 | H6: rtsp://demo.local/cam-a-07
A7: CAM-B-02 | B7: ZN-B1 | C7: PPE;RESTRICTED_ZONE | D7: ppe-v3.4 | E7: 24 | F7: ACTIVE | G7: 46247.373 | H7: rtsp://demo.local/cam-b-02
A8: CAM-M-01 | B8: ZN-M01 | C8: PPE;FIRE | D8: ppe-v3.4 | E8: 22 | F8: ACTIVE | G8: 46247.374 | H8: rtsp://demo.local/cam-m-01
A9: CAM-M-03 | B9: ZN-M01 | C9: RESTRICTED_ZONE;MAN_DOWN | D9: safety-v2.8 | E9: 24 | F9: ACTIVE | G9: 46247.374 | H9: rtsp://demo.local/cam-m-03
A10: CAM-U-01 | B10: ZN-U01 | C10: PPE;RESTRICTED_ZONE | D10: safety-v2.8 | E10: 20 | F10: ACTIVE | G10: 46247.372 | H10: rtsp://demo.local/cam-u-01
A11: CAM-W-04 | B11: ZN-W02 | C11: FORKLIFT_PROXIMITY | D11: logistics-v1.9 | E11: 25 | F11: ACTIVE | G11: 46247.374 | H11: rtsp://demo.local/cam-w-04
A12: CAM-C-01 | B12: ZN-CHEM | C12: PPE;SPILL | D12: chem-v1.2 | E12: 18 | F12: OFFLINE | G12: 46247.257 | H12: rtsp://demo.local/cam-c-01

Sheet AI_Models
A1: ESCA HSE | AI_Models | B1: ESCA HSE | AI_Models | C1: ESCA HSE | AI_Models | D1: ESCA HSE | AI_Models | E1: ESCA HSE | AI_Models | F1: ESCA HSE | AI_Models | G1: ESCA HSE | AI_Models | H1: ESCA HSE | AI_Models | I1: ESCA HSE | AI_Models | J1: ESCA HSE | AI_Models
A2: Synthetic AI model registry and validation metrics | Owner: Member 5 | Synthetic sample data | Snapshot: 2026-08-13 | B2: Synthetic AI model registry and validation metrics | Owner: Member 5 | Synthetic sample data | Snapshot: 2026-08-13 | C2: Synthetic AI model registry and validation metrics | Owner: Member 5 | Synthetic sample data | Snapshot: 2026-08-13 | D2: Synthetic AI model registry and validation metrics | Owner: Member 5 | Synthetic sample data | Snapshot: 2026-08-13 | E2: Synthetic AI model registry and validation metrics | Owner: Member 5 | Synthetic sample data | Snapshot: 2026-08-13 | F2: Synthetic AI model registry and validation metrics | Owner: Member 5 | Synthetic sample data | Snapshot: 2026-08-13 | G2: Synthetic AI model registry and validation metrics | Owner: Member 5 | Synthetic sample data | Snapshot: 2026-08-13 | H2: Synthetic AI model registry and validation metrics | Owner: Member 5 | Synthetic sample data | Snapshot: 2026-08-13 | I2: Synthetic AI model registry and validation metrics | Owner: Member 5 | Synthetic sample data | Snapshot: 2026-08-13 | J2: Synthetic AI model registry and validation metrics | Owner: Member 5 | Synthetic sample data | Snapshot: 2026-08-13
A4: model_id | B4: model_name | C4: version | D4: task_type | E4: target_labels | F4: confidence_threshold | G4: validation_precision | H4: validation_recall | I4: status | J4: deployed_at
A5: MDL-PPE-HELMET | B5: Helmet Detector | C5: 3.4.0 | D5: OBJECT_DETECTION | E5: PERSON;HARD_HAT | F5: 0.8 | G5: 0.961 | H5: 0.944 | I5: DEPLOYED | J5: 46235.208
A6: MDL-PPE-VEST | B6: Safety Vest Detector | C6: 3.2.1 | D6: OBJECT_DETECTION | E6: PERSON;HI_VIS_VEST | F6: 0.8 | G6: 0.974 | H6: 0.952 | I6: DEPLOYED | J6: 46235.208
A7: MDL-PPE-EYE | B7: Safety Goggles Detector | C7: 2.8.0 | D7: OBJECT_DETECTION | E7: PERSON;SAFETY_GOGGLES | F7: 0.78 | G7: 0.897 | H7: 0.873 | I7: DEPLOYED | J7: 46235.208
A8: MDL-GEOFENCE | B8: Restricted Zone Monitor | C8: 4.1.0 | D8: ZONE_INTRUSION | E8: PERSON;RESTRICTED_ZONE | F8: 0.85 | G8: 0.989 | H8: 0.978 | I8: DEPLOYED | J8: 46235.208
A9: MDL-FIRE | B9: Smoke and Fire Detector | C9: 2.5.2 | D9: EVENT_DETECTION | E9: SMOKE;FLAME | F9: 0.75 | G9: 0.923 | H9: 0.901 | I9: DEPLOYED | J9: 46235.208
A10: MDL-MANDOWN | B10: Man Down Detector | C10: 1.9.4 | D10: POSE_DETECTION | E10: FALL;MAN_DOWN | F10: 0.82 | G10: 0.91 | H10: 0.884 | I10: DEPLOYED | J10: 46235.208
A11: MDL-SPILL | B11: Liquid Spill Detector | C11: 0.9.0 | D11: SEGMENTATION | E11: LIQUID_SPILL | F11: 0.8 | G11: 0.785 | H11: 0.742 | I11: TRAINING
A12: MDL-FORKLIFT | B12: Forklift Proximity | C12: 2.2.0 | D12: PROXIMITY_EVENT | E12: PERSON;FORKLIFT | F12: 0.82 | G12: 0.946 | H12: 0.929 | I12: DEPLOYED | J12: 46235.208

Sheet AI_Events
A1: ESCA HSE | AI_Events | B1: ESCA HSE | AI_Events | C1: ESCA HSE | AI_Events | D1: ESCA HSE | AI_Events | E1: ESCA HSE | AI_Events | F1: ESCA HSE | AI_Events | G1: ESCA HSE | AI_Events | H1: ESCA HSE | AI_Events | I1: ESCA HSE | AI_Events | J1: ESCA HSE | AI_Events | K1: ESCA HSE | AI_Events
A2: Synthetic AI detections | Owner: Member 5 | Synthetic sample data | Snapshot: 2026-08-13 | B2: Synthetic AI detections | Owner: Member 5 | Synthetic sample data | Snapshot: 2026-08-13 | C2: Synthetic AI detections | Owner: Member 5 | Synthetic sample data | Snapshot: 2026-08-13 | D2: Synthetic AI detections | Owner: Member 5 | Synthetic sample data | Snapshot: 2026-08-13 | E2: Synthetic AI detections | Owner: Member 5 | Synthetic sample data | Snapshot: 2026-08-13 | F2: Synthetic AI detections | Owner: Member 5 | Synthetic sample data | Snapshot: 2026-08-13 | G2: Synthetic AI detections | Owner: Member 5 | Synthetic sample data | Snapshot: 2026-08-13 | H2: Synthetic AI detections | Owner: Member 5 | Synthetic sample data | Snapshot: 2026-08-13 | I2: Synthetic AI detections | Owner: Member 5 | Synthetic sample data | Snapshot: 2026-08-13 | J2: Synthetic AI detections | Owner: Member 5 | Synthetic sample data | Snapshot: 2026-08-13 | K2: Synthetic AI detections | Owner: Member 5 | Synthetic sample data | Snapshot: 2026-08-13
A4: ai_event_id | B4: detected_at | C4: event_type | D4: camera_id | E4: zone_id | F4: employee_id | G4: confidence_pct | H4: severity | I4: status | J4: action_taken | K4: linked_incident_id
A5: AIE-0001 | B5: 46247.321 | C5: PPE_VIOLATION | D5: CAM-A-07 | E5: ZN-A1 | F5: EMP-017 | G5: 0.96 | H5: HIGH | I5: OPEN | J5: Supervisor notified
A6: AIE-0002 | B6: 46247.319 | C6: PPE_VIOLATION | D6: CAM-B-02 | E6: ZN-B1 | F6: EMP-019 | G6: 0.94 | H6: MEDIUM | I6: RESOLVED | J6: Correct PPE restored
A7: AIE-0003 | B7: 46247.317 | C7: RESTRICTED_ZONE | D7: CAM-M-03 | E7: ZN-M01 | G7: 0.93 | H7: HIGH | I7: OPEN | J7: Local audio warning
A8: AIE-0004 | B8: 46247.315 | C8: PPE_VIOLATION | D8: CAM-A-01 | E8: ZN-A1 | F8: EMP-031 | G8: 0.91 | H8: MEDIUM | I8: RESOLVED | J8: Vest issued
A9: AIE-0005 | B9: 46247.271 | C9: FORKLIFT_PROXIMITY | D9: CAM-W-04 | E9: ZN-W02 | F9: EMP-033 | G9: 0.89 | H9: HIGH | I9: RESOLVED | J9: Cabin warning
A10: AIE-0006 | B10: 46247.269 | C10: RESTRICTED_ZONE | D10: CAM-U-01 | E10: ZN-U01 | F10: EMP-029 | G10: 0.97 | H10: CRITICAL | I10: OPEN | J10: No matching permit
A11: AIE-0007 | B11: 46247.267 | C11: PPE_VIOLATION | D11: CAM-M-01 | E11: ZN-M01 | F11: EMP-029 | G11: 0.95 | H11: HIGH | I11: RESOLVED | J11: Welding mask used
A12: AIE-0008 | B12: 46247.265 | C12: MAN_DOWN | D12: CAM-M-03 | E12: ZN-M01 | F12: EMP-032 | G12: 0.82 | H12: CRITICAL | I12: FALSE_POSITIVE | J12: Supervisor verified safe
A13: AIE-0009 | B13: 46247.221 | C13: SMOKE_DETECTION | D13: CAM-A-07 | E13: ZN-A1 | G13: 0.88 | H13: CRITICAL | I13: RESOLVED | J13: Hot-work plume verified
A14: AIE-0010 | B14: 46247.219 | C14: SPILL_DETECTION | D14: CAM-C-01 | E14: ZN-CHEM | G14: 0.79 | H14: MEDIUM | I14: MODEL_REVIEW | J14: Low-confidence event
A15: AIE-0011 | B15: 46247.217 | C15: PPE_VIOLATION | D15: CAM-A-07 | E15: ZN-A1 | F15: EMP-017 | G15: 0.93 | H15: HIGH | I15: RESOLVED | J15: Repeat event 2
A16: AIE-0012 | B16: 46247.215 | C16: PPE_VIOLATION | D16: CAM-A-07 | E16: ZN-A1 | F16: EMP-017 | G16: 0.92 | H16: HIGH | I16: OPEN | J16: Repeat event 3 - training action | K16: INC-2026-0081
A17: AIE-0013 | B17: 46247.171 | C17: RESTRICTED_ZONE | D17: CAM-U-01 | E17: ZN-U01 | F17: EMP-026 | G17: 0.9 | H17: MEDIUM | I17: RESOLVED | J17: Authorized employee verified
A18: AIE-0014 | B18: 46247.169 | C18: FORKLIFT_PROXIMITY | D18: CAM-W-04 | E18: ZN-W02 | F18: EMP-024 | G18: 0.86 | H18: HIGH | I18: RESOLVED | J18: Route corrected
A19: AIE-0015 | B19: 46247.167 | C19: PPE_VIOLATION | D19: CAM-B-02 | E19: ZN-B1 | F19: EMP-035 | G19: 0.89 | H19: MEDIUM | I19: OPEN | J19: Safety glasses missing
A20: AIE-0016 | B20: 46247.206 | C20: FIRE_DETECTION | D20: CAM-M-01 | E20: ZN-M01 | G20: 0.84 | H20: CRITICAL | I20: FALSE_POSITIVE | J20: Welding work under permit
A21: AIE-0017 | B21: 46247.162 | C21: PPE_VIOLATION | D21: CAM-A-01 | E21: ZN-A1 | F21: EMP-018 | G21: 0.97 | H21: HIGH | I21: RESOLVED | J21: Helmet restored
A22: AIE-0018 | B22: 46247.16 | C22: RESTRICTED_ZONE | D22: CAM-M-03 | E22: ZN-M01 | F22: EMP-021 | G22: 0.87 | H22: MEDIUM | I22: RESOLVED | J22: Work authorization confirmed

Sheet Wearable_Devices
A1: ESCA HSE | Wearable_Devices | B1: ESCA HSE | Wearable_Devices | C1: ESCA HSE | Wearable_Devices | D1: ESCA HSE | Wearable_Devices | E1: ESCA HSE | Wearable_Devices | F1: ESCA HSE | Wearable_Devices | G1: ESCA HSE | Wearable_Devices
A2: Synthetic wearable assignments | Owner: Member 5 | Synthetic sample data | Snapshot: 2026-08-13 | B2: Synthetic wearable assignments | Owner: Member 5 | Synthetic sample data | Snapshot: 2026-08-13 | C2: Synthetic wearable assignments | Owner: Member 5 | Synthetic sample data | Snapshot: 2026-08-13 | D2: Synthetic wearable assignments | Owner: Member 5 | Synthetic sample data | Snapshot: 2026-08-13 | E2: Synthetic wearable assignments | Owner: Member 5 | Synthetic sample data | Snapshot: 2026-08-13 | F2: Synthetic wearable assignments | Owner: Member 5 | Synthetic sample data | Snapshot: 2026-08-13 | G2: Synthetic wearable assignments | Owner: Member 5 | Synthetic sample data | Snapshot: 2026-08-13
A4: device_id | B4: employee_id | C4: device_type | D4: assigned_at | E4: status | F4: battery_pct | G4: last_heartbeat_at
A5: WRB-0001 | B5: EMP-017 | C5: SMART_BADGE | D5: 46023 | E5: ACTIVE | F5: 76 | G5: 46247.374
A6: WRB-0002 | B6: EMP-018 | C6: HEAT_BAND | D6: 46023 | E6: ACTIVE | F6: 62 | G6: 46247.374
A7: WRB-0003 | B7: EMP-019 | C7: SMART_BADGE | D7: 46054 | E7: ACTIVE | F7: 81 | G7: 46247.374
A8: WRB-0004 | B8: EMP-020 | C8: HEAT_BAND | D8: 46054 | E8: ACTIVE | F8: 45 | G8: 46247.373
A9: WRB-0005 | B9: EMP-021 | C9: MAN_DOWN_BADGE | D9: 46082 | E9: ACTIVE | F9: 90 | G9: 46247.374
A10: WRB-0006 | B10: EMP-022 | C10: SMART_BADGE | D10: 46082 | E10: ACTIVE | F10: 31 | G10: 46247.372
A11: WRB-0007 | B11: EMP-023 | C11: FORKLIFT_TAG | D11: 46113 | E11: ACTIVE | F11: 58 | G11: 46247.374
A12: WRB-0008 | B12: EMP-024 | C12: SMART_BADGE | D12: 46113 | E12: ACTIVE | F12: 70 | G12: 46247.374
A13: WRB-0009 | B13: EMP-026 | C13: MAN_DOWN_BADGE | D13: 46143 | E13: CHARGING | F13: 15 | G13: 46247.306
A14: WRB-0010 | B14: EMP-027 | C14: GAS_BADGE | D14: 46143 | E14: ACTIVE | F14: 66 | G14: 46247.374

Sheet Wearable_Events
A1: ESCA HSE | Wearable_Events | B1: ESCA HSE | Wearable_Events | C1: ESCA HSE | Wearable_Events | D1: ESCA HSE | Wearable_Events | E1: ESCA HSE | Wearable_Events | F1: ESCA HSE | Wearable_Events | G1: ESCA HSE | Wearable_Events | H1: ESCA HSE | Wearable_Events | I1: ESCA HSE | Wearable_Events | J1: ESCA HSE | Wearable_Events | K1: ESCA HSE | Wearable_Events
A2: Synthetic wearable alerts | Owner: Member 5 | Synthetic sample data | Snapshot: 2026-08-13 | B2: Synthetic wearable alerts | Owner: Member 5 | Synthetic sample data | Snapshot: 2026-08-13 | C2: Synthetic wearable alerts | Owner: Member 5 | Synthetic sample data | Snapshot: 2026-08-13 | D2: Synthetic wearable alerts | Owner: Member 5 | Synthetic sample data | Snapshot: 2026-08-13 | E2: Synthetic wearable alerts | Owner: Member 5 | Synthetic sample data | Snapshot: 2026-08-13 | F2: Synthetic wearable alerts | Owner: Member 5 | Synthetic sample data | Snapshot: 2026-08-13 | G2: Synthetic wearable alerts | Owner: Member 5 | Synthetic sample data | Snapshot: 2026-08-13 | H2: Synthetic wearable alerts | Owner: Member 5 | Synthetic sample data | Snapshot: 2026-08-13 | I2: Synthetic wearable alerts | Owner: Member 5 | Synthetic sample data | Snapshot: 2026-08-13 | J2: Synthetic wearable alerts | Owner: Member 5 | Synthetic sample data | Snapshot: 2026-08-13 | K2: Synthetic wearable alerts | Owner: Member 5 | Synthetic sample data | Snapshot: 2026-08-13
A4: wearable_event_id | B4: device_id | C4: employee_id | D4: captured_at | E4: metric_type | F4: value | G4: unit | H4: threshold | I4: severity | J4: status | K4: action_taken
A5: WRE-001 | B5: WRB-0001 | C5: EMP-017 | D5: 46247.257 | E5: HEART_RATE | F5: 148 | G5: bpm | H5: 130 | I5: HIGH | J5: OPEN | K5: Rest recommendation
A6: WRE-002 | B6: WRB-0002 | C6: EMP-018 | D6: 46247.301 | E6: HEAT_STRAIN | F6: 8.2 | G6: index | H6: 7 | I6: HIGH | J6: OPEN | K6: 10 minute rest cycle
A7: WRE-003 | B7: WRB-0005 | C7: EMP-021 | D7: 46247.346 | E7: MAN_DOWN | F7: 1 | G7: event | H7: 1 | I7: CRITICAL | J7: FALSE_POSITIVE | K7: Supervisor verified
A8: WRE-004 | B8: WRB-0007 | C8: EMP-023 | D8: 46247.265 | E8: FORKLIFT_PROXIMITY | F8: 1.8 | G8: m | H8: 2 | I8: HIGH | J8: RESOLVED | K8: Cabin warning
A9: WRE-005 | B9: WRB-0010 | C9: EMP-027 | D9: 46247.31 | E9: OXYGEN | F9: 18.7 | G9: % | H9: 19.5 | I9: CRITICAL | J9: OPEN | K9: Confined-space permit suspended
A10: WRE-006 | B10: WRB-0003 | C10: EMP-019 | D10: 46247.354 | E10: HEART_RATE | F10: 92 | G10: bpm | H10: 130 | I10: NORMAL | J10: CLOSED | K10: No action
A11: WRE-007 | B11: WRB-0004 | C11: EMP-020 | D11: 46247.274 | E11: HEAT_STRAIN | F11: 6.2 | G11: index | H11: 7 | I11: WARNING | J11: RESOLVED | K11: Hydration reminder
A12: WRE-008 | B12: WRB-0006 | C12: EMP-022 | D12: 46247.318 | E12: HEART_RATE | F12: 135 | G12: bpm | H12: 130 | I12: HIGH | J12: RESOLVED | K12: Short rest taken
A13: WRE-009 | B13: WRB-0008 | C13: EMP-024 | D13: 46247.363 | E13: SOS | F13: 1 | G13: event | H13: 1 | I13: CRITICAL | J13: TEST | K13: Scheduled device test
A14: WRE-010 | B14: WRB-0009 | C14: EMP-026 | D14: 46247.282 | E14: BATTERY | F14: 15 | G14: % | H14: 20 | I14: WARNING | J14: OPEN | K14: Device charging

Sheet Integrations
A1: ESCA HSE | Integrations | B1: ESCA HSE | Integrations | C1: ESCA HSE | Integrations | D1: ESCA HSE | Integrations | E1: ESCA HSE | Integrations | F1: ESCA HSE | Integrations | G1: ESCA HSE | Integrations | H1: ESCA HSE | Integrations | I1: ESCA HSE | Integrations | J1: ESCA HSE | Integrations
A2: External integration catalogue | Owner: Member 2 | Synthetic sample data | Snapshot: 2026-08-13 | B2: External integration catalogue | Owner: Member 2 | Synthetic sample data | Snapshot: 2026-08-13 | C2: External integration catalogue | Owner: Member 2 | Synthetic sample data | Snapshot: 2026-08-13 | D2: External integration catalogue | Owner: Member 2 | Synthetic sample data | Snapshot: 2026-08-13 | E2: External integration catalogue | Owner: Member 2 | Synthetic sample data | Snapshot: 2026-08-13 | F2: External integration catalogue | Owner: Member 2 | Synthetic sample data | Snapshot: 2026-08-13 | G2: External integration catalogue | Owner: Member 2 | Synthetic sample data | Snapshot: 2026-08-13 | H2: External integration catalogue | Owner: Member 2 | Synthetic sample data | Snapshot: 2026-08-13 | I2: External integration catalogue | Owner: Member 2 | Synthetic sample data | Snapshot: 2026-08-13 | J2: External integration catalogue | Owner: Member 2 | Synthetic sample data | Snapshot: 2026-08-13
A4: integration_id | B4: system_name | C4: system_type | D4: protocol | E4: direction | F4: frequency | G4: base_endpoint | H4: auth_method | I4: status | J4: owner_employee_id
A5: INT-D365 | B5: Microsoft Dynamics 365 F&O | C5: ERP | D5: OData;REST | E5: BIDIRECTIONAL | F5: REAL_TIME | G5: https://d365.example.local/api | H5: OAUTH2_CLIENT_CREDENTIALS | I5: CONNECTED | J5: EMP-007
A6: INT-HRMS | B6: HRMS | C6: HUMAN_RESOURCES | D6: REST | E6: INBOUND | F6: HOURLY | G6: https://hrms.example.local/api | H6: OAUTH2_CLIENT_CREDENTIALS | I6: CONNECTED | J6: EMP-028
A7: INT-ACCESS | B7: Access Control | C7: PHYSICAL_ACCESS | D7: WEBHOOK;REST | E7: BIDIRECTIONAL | F7: REAL_TIME | G7: https://access.example.local/api | H7: MUTUAL_TLS | I7: CONNECTED | J7: EMP-006
A8: INT-LMS | B8: Learning Management System | C8: TRAINING | D8: REST | E8: INBOUND | F8: DAILY | G8: https://lms.example.local/api | H8: OAUTH2_CLIENT_CREDENTIALS | I8: CONNECTED | J8: EMP-036
A9: INT-CCTV | B9: CCTV/VMS | C9: VIDEO_MANAGEMENT | D9: RTSP;GRPC | E9: INBOUND | F9: STREAMING | G9: rtsp://vms.example.local | H9: MUTUAL_TLS | I9: CONNECTED | J9: EMP-012
A10: INT-SCADA | B10: SCADA/IoT Gateway | C10: INDUSTRIAL_IOT | D10: MQTT;OPC-UA | E10: BIDIRECTIONAL | F10: REAL_TIME | G10: mqtt://scada.example.local | H10: CLIENT_CERTIFICATE | I10: TESTING | J10: EMP-006

Sheet API_Logs
A1: ESCA HSE | API_Logs | B1: ESCA HSE | API_Logs | C1: ESCA HSE | API_Logs | D1: ESCA HSE | API_Logs | E1: ESCA HSE | API_Logs | F1: ESCA HSE | API_Logs | G1: ESCA HSE | API_Logs | H1: ESCA HSE | API_Logs | I1: ESCA HSE | API_Logs | J1: ESCA HSE | API_Logs
A2: Synthetic integration request logs | Owner: Member 2 | Synthetic sample data | Snapshot: 2026-08-13 | B2: Synthetic integration request logs | Owner: Member 2 | Synthetic sample data | Snapshot: 2026-08-13 | C2: Synthetic integration request logs | Owner: Member 2 | Synthetic sample data | Snapshot: 2026-08-13 | D2: Synthetic integration request logs | Owner: Member 2 | Synthetic sample data | Snapshot: 2026-08-13 | E2: Synthetic integration request logs | Owner: Member 2 | Synthetic sample data | Snapshot: 2026-08-13 | F2: Synthetic integration request logs | Owner: Member 2 | Synthetic sample data | Snapshot: 2026-08-13 | G2: Synthetic integration request logs | Owner: Member 2 | Synthetic sample data | Snapshot: 2026-08-13 | H2: Synthetic integration request logs | Owner: Member 2 | Synthetic sample data | Snapshot: 2026-08-13 | I2: Synthetic integration request logs | Owner: Member 2 | Synthetic sample data | Snapshot: 2026-08-13 | J2: Synthetic integration request logs | Owner: Member 2 | Synthetic sample data | Snapshot: 2026-08-13
A4: api_log_id | B4: integration_id | C4: occurred_at | D4: method | E4: endpoint | F4: status_code | G4: response_ms | H4: retry_count | I4: outcome | J4: correlation_id
A5: API-0001 | B5: INT-D365 | C5: 46247.321 | D5: GET | E5: /api/v1/equipment/sync | F5: 200 | G5: 184 | H5: 0 | I5: SUCCESS | J5: CORR-API-0001
A6: API-0002 | B6: INT-D365 | C6: 46247.319 | D6: POST | E6: /api/v1/permits/link-workorder | F6: 200 | G6: 212 | H6: 0 | I6: SUCCESS | J6: CORR-API-0002
A7: API-0003 | B7: INT-HRMS | C7: 46247.318 | D7: GET | E7: /api/v1/employees/delta | F7: 200 | G7: 96 | H7: 0 | I7: SUCCESS | J7: CORR-API-0003
A8: API-0004 | B8: INT-ACCESS | C8: 46247.317 | D8: POST | E8: /api/v1/access/revoke | F8: 201 | G8: 78 | H8: 0 | I8: SUCCESS | J8: CORR-API-0004
A9: API-0005 | B9: INT-SCADA | C9: 46247.315 | D9: POST | E9: /api/v1/iot/telemetry | F9: 503 | G9: 5000 | H9: 0 | I9: TIMEOUT | J9: CORR-API-0005
A10: API-0006 | B10: INT-SCADA | C10: 46247.272 | D10: POST | E10: /api/v1/iot/telemetry | F10: 200 | G10: 340 | H10: 1 | I10: RETRY_SUCCESS | J10: CORR-API-0006
A11: API-0007 | B11: INT-LMS | C11: 46247.271 | D11: GET | E11: /api/v1/training/certificates | F11: 200 | G11: 143 | H11: 0 | I11: SUCCESS | J11: CORR-API-0007
A12: API-0008 | B12: INT-CCTV | C12: 46247.269 | D12: POST | E12: /api/v1/incidents/webhook | F12: 200 | G12: 61 | H12: 0 | I12: SUCCESS | J12: CORR-API-0008
A13: API-0009 | B13: INT-D365 | C13: 46247.268 | D13: GET | E13: /api/v1/equipment/list | F13: 429 | G13: 80 | H13: 0 | I13: THROTTLED | J13: CORR-API-0009
A14: API-0010 | B14: INT-D365 | C14: 46247.267 | D14: GET | E14: /api/v1/equipment/list | F14: 200 | G14: 230 | H14: 1 | I14: RETRY_SUCCESS | J14: CORR-API-0010
A15: API-0011 | B15: INT-HRMS | C15: 46247.224 | D15: GET | E15: /api/v1/departments | F15: 200 | G15: 88 | H15: 0 | I15: SUCCESS | J15: CORR-API-0011
A16: API-0012 | B16: INT-ACCESS | C16: 46247.222 | D16: GET | E16: /api/v1/access/events | F16: 200 | G16: 105 | H16: 0 | I16: SUCCESS | J16: CORR-API-0012
... A24: API-0020 | B24: INT-HRMS | C24: 46247.169 | D24: GET | E24: /api/v1/employees/delta | F24: 200 | G24: 97 | H24: 1 | I24: RETRY_SUCCESS | J24: CORR-API-0020

Sheet Integration_Outbox
A1: ESCA HSE | Integration_Outbox | B1: ESCA HSE | Integration_Outbox | C1: ESCA HSE | Integration_Outbox | D1: ESCA HSE | Integration_Outbox | E1: ESCA HSE | Integration_Outbox | F1: ESCA HSE | Integration_Outbox | G1: ESCA HSE | Integration_Outbox | H1: ESCA HSE | Integration_Outbox | I1: ESCA HSE | Integration_Outbox | J1: ESCA HSE | Integration_Outbox | K1: ESCA HSE | Integration_Outbox | L1: ESCA HSE | Integration_Outbox | M1: ESCA HSE | Integration_Outbox
A2: Retry-safe integration outbox sample | Owner: Member 2 | Synthetic sample data | Snapshot: 2026-08-13 | B2: Retry-safe integration outbox sample | Owner: Member 2 | Synthetic sample data | Snapshot: 2026-08-13 | C2: Retry-safe integration outbox sample | Owner: Member 2 | Synthetic sample data | Snapshot: 2026-08-13 | D2: Retry-safe integration outbox sample | Owner: Member 2 | Synthetic sample data | Snapshot: 2026-08-13 | E2: Retry-safe integration outbox sample | Owner: Member 2 | Synthetic sample data | Snapshot: 2026-08-13 | F2: Retry-safe integration outbox sample | Owner: Member 2 | Synthetic sample data | Snapshot: 2026-08-13 | G2: Retry-safe integration outbox sample | Owner: Member 2 | Synthetic sample data | Snapshot: 2026-08-13 | H2: Retry-safe integration outbox sample | Owner: Member 2 | Synthetic sample data | Snapshot: 2026-08-13 | I2: Retry-safe integration outbox sample | Owner: Member 2 | Synthetic sample data | Snapshot: 2026-08-13 | J2: Retry-safe integration outbox sample | Owner: Member 2 | Synthetic sample data | Snapshot: 2026-08-13 | K2: Retry-safe integration outbox sample | Owner: Member 2 | Synthetic sample data | Snapshot: 2026-08-13 | L2: Retry-safe integration outbox sample | Owner: Member 2 | Synthetic sample data | Snapshot: 2026-08-13 | M2: Retry-safe integration outbox sample | Owner: Member 2 | Synthetic sample data | Snapshot: 2026-08-13
A4: outbox_id | B4: created_at | C4: aggregate_type | D4: aggregate_id | E4: event_type | F4: destination_integration_id | G4: status | H4: attempt_count | I4: next_retry_at | J4: processed_at | K4: correlation_id | L4: idempotency_key | M4: last_error
A5: OBX-001 | B5: 46247.188 | C5: PERMIT | D5: PTW-2026-0412 | E5: PERMIT_WORKORDER_LINKED | F5: INT-D365 | G5: PROCESSED | H5: 1 | J5: 46247.195 | K5: CORR-OBX-001 | L5: permit_workorder_linked:PTW-2026-0412
A6: OBX-002 | B6: 46247.229 | C6: EMPLOYEE | D6: EMP-026 | E6: ACCESS_REVOKED | F6: INT-ACCESS | G6: PROCESSED | H6: 1 | J6: 46247.193 | K6: CORR-OBX-002 | L6: access_revoked:EMP-026
A7: OBX-003 | B7: 46247.271 | C7: SENSOR | D7: SNS-CS-02 | E7: TELEMETRY_RECEIVED | F7: INT-SCADA | G7: PROCESSED | H7: 2 | J7: 46247.192 | K7: CORR-OBX-003 | L7: telemetry_received:SNS-CS-02
A8: OBX-004 | B8: 46247.312 | C8: INCIDENT | D8: INC-2026-0089 | E8: CREATE_WORK_ORDER | F8: INT-D365 | G8: RETRY_SCHEDULED | H8: 2 | I8: 46247.396 | K8: CORR-OBX-004 | L8: create_work_order:INC-2026-0089 | M8: D365_TEMPORARY_FAILURE
A9: OBX-005 | B9: 46247.354 | C9: AI_EVENT | D9: AIE-0012 | E9: ASSIGN_TRAINING | F9: INT-LMS | G9: PROCESSED | H9: 1 | J9: 46247.302 | K9: CORR-OBX-005 | L9: assign_training:AIE-0012
A10: OBX-006 | B10: 46247.396 | C10: REPORT | D10: RRN-001 | E10: PUBLISH_DATASET | F10: INT-D365 | G10: PENDING | H10: 0 | I10: 46247.417 | K10: CORR-OBX-006 | L10: publish_dataset:RRN-001

Sheet QA_Sessions
A1: ESCA HSE | QA_Sessions | B1: ESCA HSE | QA_Sessions | C1: ESCA HSE | QA_Sessions | D1: ESCA HSE | QA_Sessions | E1: ESCA HSE | QA_Sessions | F1: ESCA HSE | QA_Sessions | G1: ESCA HSE | QA_Sessions
A2: Admin conversational Q&A sessions | Owner: Member 5 | Synthetic sample data | Snapshot: 2026-08-13 | B2: Admin conversational Q&A sessions | Owner: Member 5 | Synthetic sample data | Snapshot: 2026-08-13 | C2: Admin conversational Q&A sessions | Owner: Member 5 | Synthetic sample data | Snapshot: 2026-08-13 | D2: Admin conversational Q&A sessions | Owner: Member 5 | Synthetic sample data | Snapshot: 2026-08-13 | E2: Admin conversational Q&A sessions | Owner: Member 5 | Synthetic sample data | Snapshot: 2026-08-13 | F2: Admin conversational Q&A sessions | Owner: Member 5 | Synthetic sample data | Snapshot: 2026-08-13 | G2: Admin conversational Q&A sessions | Owner: Member 5 | Synthetic sample data | Snapshot: 2026-08-13
A4: session_id | B4: admin_user_id | C4: started_at | D4: ended_at | E4: status | F4: purpose | G4: sensitivity
A5: QAS-001 | B5: USR-008 | C5: 46247.25 | D5: 46247.256 | E5: CLOSED | F5: Review overdue HSE actions | G5: INTERNAL
A6: QAS-002 | B6: USR-010 | C6: 46247.292 | E6: ACTIVE | F6: Prepare shift safety briefing | G6: INTERNAL
A7: QAS-003 | B7: USR-008 | C7: 46246.458 | D7: 46246.463 | E7: CLOSED | F7: Review permit risks | G7: INTERNAL
A8: QAS-004 | B8: USR-020 | C8: 46246.333 | D8: 46246.335 | E8: DENIED | F8: Attempted restricted medical query | G8: RESTRICTED

Sheet QA_Messages
A1: ESCA HSE | QA_Messages | B1: ESCA HSE | QA_Messages | C1: ESCA HSE | QA_Messages | D1: ESCA HSE | QA_Messages | E1: ESCA HSE | QA_Messages | F1: ESCA HSE | QA_Messages | G1: ESCA HSE | QA_Messages | H1: ESCA HSE | QA_Messages | I1: ESCA HSE | QA_Messages
A2: Synthetic admin Q&A messages and policy blocks | Owner: Member 5 | Synthetic sample data | Snapshot: 2026-08-13 | B2: Synthetic admin Q&A messages and policy blocks | Owner: Member 5 | Synthetic sample data | Snapshot: 2026-08-13 | C2: Synthetic admin Q&A messages and policy blocks | Owner: Member 5 | Synthetic sample data | Snapshot: 2026-08-13 | D2: Synthetic admin Q&A messages and policy blocks | Owner: Member 5 | Synthetic sample data | Snapshot: 2026-08-13 | E2: Synthetic admin Q&A messages and policy blocks | Owner: Member 5 | Synthetic sample data | Snapshot: 2026-08-13 | F2: Synthetic admin Q&A messages and policy blocks | Owner: Member 5 | Synthetic sample data | Snapshot: 2026-08-13 | G2: Synthetic admin Q&A messages and policy blocks | Owner: Member 5 | Synthetic sample data | Snapshot: 2026-08-13 | H2: Synthetic admin Q&A messages and policy blocks | Owner: Member 5 | Synthetic sample data | Snapshot: 2026-08-13 | I2: Synthetic admin Q&A messages and policy blocks | Owner: Member 5 | Synthetic sample data | Snapshot: 2026-08-13
A4: message_id | B4: session_id | C4: message_order | D4: role | E4: created_at | F4: content | G4: source_count | H4: safety_flag | I4: status
A5: QAM-0001 | B5: QAS-001 | C5: 1 | D5: USER | E5: 46247.251 | F5: Show overdue CAPAs and their owners. | H5: SAFE | I5: COMPLETED
A6: QAM-0002 | B6: QAS-001 | C6: 2 | D6: ASSISTANT | E6: 46247.251 | F6: Five open CAPAs are overdue in the synthetic snapshot; results are grouped by owner. | G6: 5 | H6: SAFE | I6: COMPLETED
A7: QAM-0003 | B7: QAS-001 | C7: 3 | D7: USER | E7: 46247.252 | F7: Which active permits expire within six hours? | H7: SAFE | I7: COMPLETED
A8: QAM-0004 | B8: QAS-001 | C8: 4 | D8: ASSISTANT | E8: 46247.253 | F8: The permitted tool query returned the current active permits and their expiry flags. | G8: 5 | H8: SAFE | I8: COMPLETED
A9: QAM-0005 | B9: QAS-002 | C9: 1 | D9: USER | E9: 46247.292 | F9: Summarize critical alerts for the shift briefing. | H9: SAFE | I9: COMPLETED
A10: QAM-0006 | B10: QAS-002 | C10: 2 | D10: ASSISTANT | E10: 46247.293 | F10: Critical synthetic alerts include a low-oxygen reading, an overdue permit, and high-risk reviews. | G10: 3 | H10: SAFE | I10: COMPLETED
A11: QAM-0007 | B11: QAS-003 | C11: 1 | D11: USER | E11: 46246.459 | F11: Explain the SIMOPS conflict for PTW-2026-0412. | H11: SAFE | I11: COMPLETED
A12: QAM-0008 | B12: QAS-003 | C12: 2 | D12: ASSISTANT | E12: 46246.46 | F12: A hot-work and flammable-material proximity rule was triggered at 4.2 metres. | G12: 1 | H12: SAFE | I12: COMPLETED
A13: QAM-0009 | B13: QAS-004 | C13: 1 | D13: USER | E13: 46246.334 | F13: List diagnoses for all employees. | H13: RESTRICTED_REQUEST | I13: BLOCKED
A14: QAM-0010 | B14: QAS-004 | C14: 2 | D14: ASSISTANT | E14: 46246.335 | F14: I cannot provide restricted medical details. Only authorized occupational-health roles may access them. | G14: 0 | H14: POLICY_BLOCK | I14: COMPLETED

Sheet QA_Tool_Calls
A1: ESCA HSE | QA_Tool_Calls | B1: ESCA HSE | QA_Tool_Calls | C1: ESCA HSE | QA_Tool_Calls | D1: ESCA HSE | QA_Tool_Calls | E1: ESCA HSE | QA_Tool_Calls | F1: ESCA HSE | QA_Tool_Calls | G1: ESCA HSE | QA_Tool_Calls | H1: ESCA HSE | QA_Tool_Calls | I1: ESCA HSE | QA_Tool_Calls | J1: ESCA HSE | QA_Tool_Calls | K1: ESCA HSE | QA_Tool_Calls
A2: Audited read-only Q&A tool calls | Owner: Member 5 + Member 1 | Synthetic sample data | Snapshot: 2026-08-13 | B2: Audited read-only Q&A tool calls | Owner: Member 5 + Member 1 | Synthetic sample data | Snapshot: 2026-08-13 | C2: Audited read-only Q&A tool calls | Owner: Member 5 + Member 1 | Synthetic sample data | Snapshot: 2026-08-13 | D2: Audited read-only Q&A tool calls | Owner: Member 5 + Member 1 | Synthetic sample data | Snapshot: 2026-08-13 | E2: Audited read-only Q&A tool calls | Owner: Member 5 + Member 1 | Synthetic sample data | Snapshot: 2026-08-13 | F2: Audited read-only Q&A tool calls | Owner: Member 5 + Member 1 | Synthetic sample data | Snapshot: 2026-08-13 | G2: Audited read-only Q&A tool calls | Owner: Member 5 + Member 1 | Synthetic sample data | Snapshot: 2026-08-13 | H2: Audited read-only Q&A tool calls | Owner: Member 5 + Member 1 | Synthetic sample data | Snapshot: 2026-08-13 | I2: Audited read-only Q&A tool calls | Owner: Member 5 + Member 1 | Synthetic sample data | Snapshot: 2026-08-13 | J2: Audited read-only Q&A tool calls | Owner: Member 5 + Member 1 | Synthetic sample data | Snapshot: 2026-08-13 | K2: Audited read-only Q&A tool calls | Owner: Member 5 + Member 1 | Synthetic sample data | Snapshot: 2026-08-13
A4: tool_call_id | B4: message_id | C4: tool_name | D4: entity_type | E4: query_summary | F4: started_at | G4: completed_at | H4: rows_returned | I4: outcome | J4: audit_id | K4: write_performed
A5: QAT-001 | B5: QAM-0002 | C5: list_overdue_capas | D5: CAPA | E5: status open and due_date before snapshot | F5: 46247.252 | G5: 46247.252 | H5: 5 | I5: SUCCESS | J5: AUD-00001 | K5: FALSE
A6: QAT-002 | B6: QAM-0004 | C6: list_expiring_permits | D6: PERMIT | E6: active permits expiring within six hours | F6: 46247.253 | G6: 46247.253 | H6: 5 | I6: SUCCESS | J6: AUD-00002 | K6: FALSE
A7: QAT-003 | B7: QAM-0006 | C7: list_critical_alerts | D7: ALERT | E7: critical unresolved alerts for current shift | F7: 46247.293 | G7: 46247.293 | H7: 3 | I7: SUCCESS | J7: AUD-00003 | K7: FALSE
A8: QAT-004 | B8: QAM-0008 | C8: get_simops_conflict | D8: SIMOPS | E8: conflict for PTW-2026-0412 | F8: 46246.46 | G8: 46246.46 | H8: 1 | I8: SUCCESS | J8: AUD-00004 | K8: FALSE
A9: QAT-005 | B9: QAM-0010 | C9: get_medical_diagnoses | D9: MEDICAL | E9: all employee diagnoses | F9: 46246.335 | G9: 46246.335 | H9: 0 | I9: DENIED | J9: AUD-00005 | K9: FALSE

Sheet Notifications
A1: ESCA HSE | Notifications | B1: ESCA HSE | Notifications | C1: ESCA HSE | Notifications | D1: ESCA HSE | Notifications | E1: ESCA HSE | Notifications | F1: ESCA HSE | Notifications | G1: ESCA HSE | Notifications | H1: ESCA HSE | Notifications | I1: ESCA HSE | Notifications | J1: ESCA HSE | Notifications | K1: ESCA HSE | Notifications | L1: ESCA HSE | Notifications | M1: ESCA HSE | Notifications | N1: ESCA HSE | Notifications
A2: In-app notification records | Owner: Member 4 + Member 1 | Synthetic sample data | Snapshot: 2026-08-13 | B2: In-app notification records | Owner: Member 4 + Member 1 | Synthetic sample data | Snapshot: 2026-08-13 | C2: In-app notification records | Owner: Member 4 + Member 1 | Synthetic sample data | Snapshot: 2026-08-13 | D2: In-app notification records | Owner: Member 4 + Member 1 | Synthetic sample data | Snapshot: 2026-08-13 | E2: In-app notification records | Owner: Member 4 + Member 1 | Synthetic sample data | Snapshot: 2026-08-13 | F2: In-app notification records | Owner: Member 4 + Member 1 | Synthetic sample data | Snapshot: 2026-08-13 | G2: In-app notification records | Owner: Member 4 + Member 1 | Synthetic sample data | Snapshot: 2026-08-13 | H2: In-app notification records | Owner: Member 4 + Member 1 | Synthetic sample data | Snapshot: 2026-08-13 | I2: In-app notification records | Owner: Member 4 + Member 1 | Synthetic sample data | Snapshot: 2026-08-13 | J2: In-app notification records | Owner: Member 4 + Member 1 | Synthetic sample data | Snapshot: 2026-08-13 | K2: In-app notification records | Owner: Member 4 + Member 1 | Synthetic sample data | Snapshot: 2026-08-13 | L2: In-app notification records | Owner: Member 4 + Member 1 | Synthetic sample data | Snapshot: 2026-08-13 | M2: In-app notification records | Owner: Member 4 + Member 1 | Synthetic sample data | Snapshot: 2026-08-13 | N2: In-app notification records | Owner: Member 4 + Member 1 | Synthetic sample data | Snapshot: 2026-08-13
A4: notification_id | B4: created_at | C4: type | D4: severity | E4: entity_type | F4: entity_id | G4: recipient_type | H4: recipient_id | I4: title | J4: message | K4: status | L4: read_at | M4: idempotency_key | N4: source_service
A5: NTF-0001 | B5: 46247.368 | C5: PERMIT_EXPIRING | D5: WARNING | E5: PERMIT | F5: PTW-2026-0412 | G5: ROLE | H5: ROLE-HSE-OFF | I5: Permit expires soon | J5: Hot-work permit expires within 2 hours | K5: UNREAD | M5: permit_expiring:PTW-2026-0412:2026-08-13 | N5: automation-agent
A6: NTF-0002 | B6: 46247.366 | C6: PERMIT_OVERDUE | D6: CRITICAL | E6: PERMIT | F6: PTW-2026-0406 | G6: ROLE | H6: ROLE-HSE-MGR | I6: Active permit overdue | J6: Permit remains active after expiry | K6: UNREAD | M6: permit_overdue:PTW-2026-0406:2026-08-13 | N6: automation-agent
A7: NTF-0003 | B7: 46247.364 | C7: TRAINING_EXPIRY | D7: WARNING | E7: CERTIFICATE | F7: CERT-001 | G7: USER | H7: USR-017 | I7: LOTO certificate expiring | J7: Certificate expires in 7 days | K7: UNREAD | M7: training_expiry:CERT-001:2026-08-13 | N7: automation-agent
A8: NTF-0004 | B8: 46247.362 | C8: TRAINING_EXPIRED | D8: CRITICAL | E8: CERTIFICATE | F8: CERT-002 | G8: ROLE | H8: ROLE-HSE-MGR | I8: MV certificate expired | J8: Access review required | K8: READ | L8: 46247.372 | M8: training_expired:CERT-002:2026-08-13 | N8: automation-agent
A9: NTF-0005 | B9: 46247.36 | C9: CAPA_OVERDUE | D9: HIGH | E9: CAPA | F9: CAPA-001 | G9: USER | H9: USR-015 | I9: CAPA overdue | J9: Machine guard action is overdue | K9: UNREAD | M9: capa_overdue:CAPA-001:2026-08-13 | N9: automation-agent
A10: NTF-0006 | B10: 46247.358 | C10: CAPA_ESCALATION | D10: CRITICAL | E10: CAPA | F10: CAPA-006 | G10: ROLE | H10: ROLE-HSE-MGR | I10: CAPA escalation | J10: Cable rerouting action overdue >7 days | K10: UNREAD | M10: capa_escalation:CAPA-006:2026-08-13 | N10: automation-agent
A11: NTF-0007 | B11: 46247.314 | C11: RISK_REVIEW_OVERDUE | D11: CRITICAL | E11: RISK | F11: HZ-004 | G11: ROLE | H11: ROLE-HSE-MGR | I11: High risk needs review | J11: Forklift collision risk review overdue | K11: UNREAD | M11: risk_review_overdue:HZ-004:2026-08-13 | N11: automation-agent
A12: NTF-0008 | B12: 46247.312 | C12: FIRE_ACTION | D12: CRITICAL | E12: FIRE_EQUIPMENT | F12: FE-A-014 | G12: USER | H12: USR-015 | I12: Expired extinguisher | J12: Immediate replacement required | K12: READ | L12: 46247.372 | M12: fire_action:FE-A-014:2026-08-13 | N12: fire-service
A13: NTF-0009 | B13: 46247.31 | C13: PPE_LOW_STOCK | D13: WARNING | E13: PPE_ITEM | F13: PPE-003 | G13: USER | H13: USR-004 | I13: PPE below threshold | J13: Mechanical glove stock below reorder level | K13: UNREAD | M13: ppe_low_stock:PPE-003:2026-08-13 | N13: inventory-service
A14: NTF-0010 | B14: 46247.308 | C14: INSPECTION_OVERDUE | D14: HIGH | E14: INSPECTION | F14: INS-2026-0128 | G14: USER | H14: USR-011 | I14: Safety walk overdue | J14: Warehouse safety walk not completed | K14: UNREAD | M14: inspection_overdue:INS-2026-0128:2026-08-13 | N14: inspection-service
A15: NTF-0011 | B15: 46247.306 | C15: SDS_EXPIRED | D15: HIGH | E15: SDS | F15: SDS-006 | G15: USER | H15: USR-005 | I15: SDS update required | J15: Current SDS missing/expired for CHM-006 | K15: UNREAD | M15: sds_expired:SDS-006:2026-08-13 | N15: hazmat-service
A16: NTF-0012 | B16: 46247.303 | C16: MEDICAL_EXAM_DUE | D16: WARNING | E16: HEALTH_EXAM | F16: HEX-001 | G16: USER | H16: USR-009 | I16: Medical exam overdue | J16: Restricted clinic reminder | K16: READ | L16: 46247.372 | M16: medical_exam_due:HEX-001:2026-08-13 | N16: health-service
A17: NTF-0013 | B17: 46247.26 | C17: O2_LOW | D17: CRITICAL | E17: SENSOR | F17: SNS-CS-02 | G17: ROLE | H17: ROLE-HSE-MGR | I17: Low oxygen detected | J17: Confined-space permit suspended | K17: READ | L17: 46247.372 | M17: o2_low:SNS-CS-02:2026-08-13 | N17: iot-service
A18: NTF-0014 | B18: 46247.258 | C18: PPE_VIOLATION | D18: HIGH | E18: AI_EVENT | F18: AIE-0001 | G18: USER | H18: USR-013 | I18: PPE violation | J18: Helmet missing on CAM-A-07 | K18: READ | L18: 46247.372 | M18: ppe_violation:AIE-0001:2026-08-13 | N18: ai-inference
A19: NTF-0015 | B19: 46247.256 | C19: INTEGRATION_FAILURE | D19: HIGH | E19: INTEGRATION | F19: INT-SCADA | G19: USER | H19: USR-006 | I19: SCADA telemetry timeout | J19: Retry initiated | K19: READ | L19: 46247.372 | M19: integration_failure:INT-SCADA:2026-08-13 | N19: integration-service
A20: NTF-0016 | B20: 46247.253 | C20: AUTOMATION_FAILURE | D20: HIGH | E20: AUTOMATION_RUN | F20: RUN-014 | G20: ROLE | H20: ROLE-HSE-MGR | I20: Automation job failed | J20: Spring API unavailable | K20: UNREAD | M20: automation_failure:RUN-014:2026-08-13 | N20: automation-agent
A21: NTF-0017 | B21: 46247.251 | C21: PERMIT_SUSPENDED | D21: CRITICAL | E21: PERMIT | F21: PTW-2026-0409 | G21: ROLE | H21: ROLE-HSE-MGR | I21: Confined-space permit suspended | J21: O2 below safe limit | K21: READ | L21: 46247.372 | M21: permit_suspended:PTW-2026-0409:2026-08-13 | N21: permit-service
A22: NTF-0018 | B22: 46247.291 | C22: CERTIFICATE_RENEWAL | D22: INFO | E22: CERTIFICATE | F22: CERT-023 | G22: USER | H22: USR-017 | I22: Renewal booked | J22: LOTO renewal has been scheduled | K22: READ | L22: 46247.372 | M22: certificate_renewal:CERT-023:2026-08-13 | N22: training-service

Sheet Audit_Log
A1: ESCA HSE | Audit_Log | B1: ESCA HSE | Audit_Log | C1: ESCA HSE | Audit_Log | D1: ESCA HSE | Audit_Log | E1: ESCA HSE | Audit_Log | F1: ESCA HSE | Audit_Log | G1: ESCA HSE | Audit_Log | H1: ESCA HSE | Audit_Log | I1: ESCA HSE | Audit_Log | J1: ESCA HSE | Audit_Log | K1: ESCA HSE | Audit_Log
A2: Append-only audit sample | Owner: Member 1 | Synthetic sample data | Snapshot: 2026-08-13 | B2: Append-only audit sample | Owner: Member 1 | Synthetic sample data | Snapshot: 2026-08-13 | C2: Append-only audit sample | Owner: Member 1 | Synthetic sample data | Snapshot: 2026-08-13 | D2: Append-only audit sample | Owner: Member 1 | Synthetic sample data | Snapshot: 2026-08-13 | E2: Append-only audit sample | Owner: Member 1 | Synthetic sample data | Snapshot: 2026-08-13 | F2: Append-only audit sample | Owner: Member 1 | Synthetic sample data | Snapshot: 2026-08-13 | G2: Append-only audit sample | Owner: Member 1 | Synthetic sample data | Snapshot: 2026-08-13 | H2: Append-only audit sample | Owner: Member 1 | Synthetic sample data | Snapshot: 2026-08-13 | I2: Append-only audit sample | Owner: Member 1 | Synthetic sample data | Snapshot: 2026-08-13 | J2: Append-only audit sample | Owner: Member 1 | Synthetic sample data | Snapshot: 2026-08-13 | K2: Append-only audit sample | Owner: Member 1 | Synthetic sample data | Snapshot: 2026-08-13
A4: audit_id | B4: occurred_at | C4: actor_type | D4: actor_id | E4: action | F4: entity_type | G4: entity_id | H4: result | I4: ip_or_source | J4: correlation_id | K4: immutable_hash
A5: AUD-00001 | B5: 46247.322 | C5: USER | D5: USR-008 | E5: VIEW | F5: INCIDENT | G5: INC-2026-0089 | H5: SUCCESS | I5: 10.14.2.61 | J5: CORR-AUD-0001 | K5: sha256-demo-audit-00001
A6: AUD-00002 | B6: 46247.321 | C6: USER | D6: USR-010 | E6: UPDATE | F6: PERMIT | G6: PTW-2026-0412 | H6: SUCCESS | I6: 10.14.3.22 | J6: CORR-AUD-0002 | K6: sha256-demo-audit-00002
A7: AUD-00003 | B7: 46247.319 | C7: SERVICE | D7: iot-service | E7: AUTO_SUSPEND | F7: PERMIT | G7: PTW-2026-0409 | H7: SUCCESS | I7: internal | J7: CORR-AUD-0003 | K7: sha256-demo-audit-00003
A8: AUD-00004 | B8: 46247.318 | C8: USER | D8: USR-009 | E8: VIEW | F8: CLINIC_VISIT | G8: MED-0242 | H8: SUCCESS | I8: 10.14.7.09 | J8: CORR-AUD-0004 | K8: sha256-demo-audit-00004
A9: AUD-00005 | B9: 46247.317 | C9: USER | D9: USR-010 | E9: CREATE | F9: INSPECTION | G9: INS-2026-0129 | H9: SUCCESS | I9: 10.14.3.41 | J9: CORR-AUD-0005 | K9: sha256-demo-audit-00005
A10: AUD-00006 | B10: 46247.315 | C10: USER | D10: USR-006 | E10: UPDATE | F10: FIRE_EQUIPMENT | G10: FE-A-014 | H10: SUCCESS | I10: 10.14.3.18 | J10: CORR-AUD-0006 | K10: sha256-demo-audit-00006
A11: AUD-00007 | B11: 46247.272 | C11: SERVICE | D11: INT-D365 | E11: API_READ | F11: EQUIPMENT | G11: SYNC-BATCH-018 | H11: SUCCESS | I11: 10.20.1.5 | J11: CORR-AUD-0007 | K11: sha256-demo-audit-00007
A12: AUD-00008 | B12: 46247.271 | C12: UNKNOWN | D12: unknown | E12: AUTH_FAIL | F12: USER | G12: unknown | H12: DENIED | I12: 41.33.x.x | J12: CORR-AUD-0008 | K12: sha256-demo-audit-00008
A13: AUD-00009 | B13: 46247.269 | C13: USER | D13: USR-008 | E13: EXPORT | F13: REPORT | G13: INCIDENT_REPORT | H13: SUCCESS | I13: 10.14.2.61 | J13: CORR-AUD-0009 | K13: sha256-demo-audit-00009
A14: AUD-00010 | B14: 46247.268 | C14: USER | D14: USR-020 | E14: VIEW | F14: RISK | G14: HZ-001 | H14: SUCCESS | I14: VPN-gw | J14: CORR-AUD-0010 | K14: sha256-demo-audit-00010
A15: AUD-00011 | B15: 46247.267 | C15: USER | D15: USR-010 | E15: SIGN | F15: PERMIT | G15: PTW-2026-0411 | H15: SUCCESS | I15: 10.14.3.22 | J15: CORR-AUD-0011 | K15: sha256-demo-audit-00011
A16: AUD-00012 | B16: 46247.265 | C16: SERVICE | D16: backup-service | E16: BACKUP | F16: DATABASE | G16: SNAPSHOT-20260813 | H16: SUCCESS | I16: internal | J16: CORR-AUD-0012 | K16: sha256-demo-audit-00012
... A24: AUD-00020 | B24: 46247.171 | C24: SERVICE | D24: automation-agent | E24: NOTIFY | F24: CAPA | G24: CAPA-001 | H24: FAILED | I24: internal | J24: CORR-AUD-0020 | K24: sha256-demo-audit-00020

Sheet Security_Events
A1: ESCA HSE | Security_Events | B1: ESCA HSE | Security_Events | C1: ESCA HSE | Security_Events | D1: ESCA HSE | Security_Events | E1: ESCA HSE | Security_Events | F1: ESCA HSE | Security_Events | G1: ESCA HSE | Security_Events | H1: ESCA HSE | Security_Events | I1: ESCA HSE | Security_Events | J1: ESCA HSE | Security_Events
A2: Authentication, authorization and security events | Owner: Member 1 | Synthetic sample data | Snapshot: 2026-08-13 | B2: Authentication, authorization and security events | Owner: Member 1 | Synthetic sample data | Snapshot: 2026-08-13 | C2: Authentication, authorization and security events | Owner: Member 1 | Synthetic sample data | Snapshot: 2026-08-13 | D2: Authentication, authorization and security events | Owner: Member 1 | Synthetic sample data | Snapshot: 2026-08-13 | E2: Authentication, authorization and security events | Owner: Member 1 | Synthetic sample data | Snapshot: 2026-08-13 | F2: Authentication, authorization and security events | Owner: Member 1 | Synthetic sample data | Snapshot: 2026-08-13 | G2: Authentication, authorization and security events | Owner: Member 1 | Synthetic sample data | Snapshot: 2026-08-13 | H2: Authentication, authorization and security events | Owner: Member 1 | Synthetic sample data | Snapshot: 2026-08-13 | I2: Authentication, authorization and security events | Owner: Member 1 | Synthetic sample data | Snapshot: 2026-08-13 | J2: Authentication, authorization and security events | Owner: Member 1 | Synthetic sample data | Snapshot: 2026-08-13
A4: security_event_id | B4: occurred_at | C4: event_type | D4: severity | E4: user_id | F4: ip_or_source | G4: risk_score | H4: status | I4: action_taken | J4: correlation_id
A5: SEC-001 | B5: 46247.056 | C5: FAILED_LOGIN | D5: MEDIUM | F5: 41.33.x.x | G5: 45 | H5: INVESTIGATING | I5: ATTEMPT_COUNTED | J5: CORR-SEC-001
A6: SEC-002 | B6: 46247.097 | C6: IP_BLOCKED | D6: HIGH | F6: 41.33.x.x | G6: 82 | H6: MITIGATED | I6: IP_BLOCKED_24H | J6: CORR-SEC-002
A7: SEC-003 | B7: 46247.139 | C7: SESSION_TIMEOUT | D7: LOW | E7: USR-013 | F7: 10.14.x.x | G7: 5 | H7: CLOSED | I7: SESSION_TERMINATED | J7: CORR-SEC-003
A8: SEC-004 | B8: 46247.181 | C8: ROLE_CHANGE | D8: MEDIUM | E8: USR-020 | F8: 10.14.x.x | G8: 30 | H8: CLOSED | I8: TEMPORARY_SCOPE_APPLIED | J8: CORR-SEC-004
A9: SEC-005 | B9: 46247.222 | C9: FORBIDDEN_MEDICAL_ACCESS | D9: HIGH | E9: USR-010 | F9: 10.14.x.x | G9: 70 | H9: MITIGATED | I9: ACCESS_DENIED_AND_AUDITED | J9: CORR-SEC-005
A10: SEC-006 | B10: 46247.264 | C10: API_TOKEN_EXPIRED | D10: MEDIUM | E10: SVC-AUTO-001 | F10: internal | G10: 40 | H10: CLOSED | I10: TOKEN_REFRESHED | J10: CORR-SEC-006
A11: SEC-007 | B11: 46246.306 | C11: RATE_LIMIT_TRIGGERED | D11: MEDIUM | E11: USR-007 | F11: internal | G11: 35 | H11: CLOSED | I11: BACKOFF_APPLIED | J11: CORR-SEC-007
A12: SEC-008 | B12: 46246.347 | C12: BACKUP_INTEGRITY | D12: INFO | F12: internal | G12: 0 | H12: CLOSED | I12: BACKUP_VERIFIED | J12: CORR-SEC-008

Sheet Automation_Rules
A1: ESCA HSE | Automation_Rules | B1: ESCA HSE | Automation_Rules | C1: ESCA HSE | Automation_Rules | D1: ESCA HSE | Automation_Rules | E1: ESCA HSE | Automation_Rules | F1: ESCA HSE | Automation_Rules | G1: ESCA HSE | Automation_Rules | H1: ESCA HSE | Automation_Rules | I1: ESCA HSE | Automation_Rules | J1: ESCA HSE | Automation_Rules | K1: ESCA HSE | Automation_Rules | L1: ESCA HSE | Automation_Rules
A2: Scheduled automation rule configuration | Owner: Member 4 | Synthetic sample data | Snapshot: 2026-08-13 | B2: Scheduled automation rule configuration | Owner: Member 4 | Synthetic sample data | Snapshot: 2026-08-13 | C2: Scheduled automation rule configuration | Owner: Member 4 | Synthetic sample data | Snapshot: 2026-08-13 | D2: Scheduled automation rule configuration | Owner: Member 4 | Synthetic sample data | Snapshot: 2026-08-13 | E2: Scheduled automation rule configuration | Owner: Member 4 | Synthetic sample data | Snapshot: 2026-08-13 | F2: Scheduled automation rule configuration | Owner: Member 4 | Synthetic sample data | Snapshot: 2026-08-13 | G2: Scheduled automation rule configuration | Owner: Member 4 | Synthetic sample data | Snapshot: 2026-08-13 | H2: Scheduled automation rule configuration | Owner: Member 4 | Synthetic sample data | Snapshot: 2026-08-13 | I2: Scheduled automation rule configuration | Owner: Member 4 | Synthetic sample data | Snapshot: 2026-08-13 | J2: Scheduled automation rule configuration | Owner: Member 4 | Synthetic sample data | Snapshot: 2026-08-13 | K2: Scheduled automation rule configuration | Owner: Member 4 | Synthetic sample data | Snapshot: 2026-08-13 | L2: Scheduled automation rule configuration | Owner: Member 4 | Synthetic sample data | Snapshot: 2026-08-13
A4: rule_id | B4: rule_name | C4: entity_type | D4: schedule_cron | E4: timezone | F4: condition_summary | G4: action_endpoint | H4: severity | I4: active_flag | J4: owner | K4: threshold_value | L4: threshold_unit
A5: AUT-001 | B5: Expired or overdue permits | C5: PERMIT | D5: */5 * * * * | E5: Africa/Cairo | F5: ACTIVE permit with expiry_at <= now | G5: /api/v1/permits/{id}/flag-expired | H5: CRITICAL | I5: TRUE | J5: Member 4 | K5: 0 | L5: minutes
A6: AUT-002 | B6: Training certificate expiry | C6: CERTIFICATE | D6: 0 9 * * * | E6: Africa/Cairo | F6: VALID certificate expires in 30/14/7/0 days | G6: /api/v1/notifications | H6: WARNING | I6: TRUE | J6: Member 4 | K6: 30,14,7,0 | L6: days
A7: AUT-003 | B7: Overdue CAPA escalation | C7: CAPA | D7: 15 * * * * | E7: Africa/Cairo | F7: OPEN/IN_PROGRESS CAPA due_date < today | G7: /api/v1/capas/{id}/escalate | H7: HIGH | I7: TRUE | J7: Member 4 | K7: 1,3,7 | L7: days overdue
A8: AUT-004 | B8: High risk review overdue | C8: RISK | D8: 30 9 * * * | E8: Africa/Cairo | F8: Active risk score >=15 and review older than N days | G8: /api/v1/risks/{id}/flag-review | H8: CRITICAL | I8: TRUE | J8: Member 4 | K8: 30 | L8: days
